Workbook

Sheet Sheet1
A1: Country | B1: Subnational region | C1: Malaria Incidence | D1: IVM Target Population | E1: IVM Coverage | F1: ALBIVM Target Population | G1: ALBIVM Coverage | H1: Total population | I1: Prevalence of Loa Loa | J1: Uncomplicated malaria cases (per 100 000) | K1: Severe Malaria Cases (per 100000) | L1: Estimated Uncomplicated Cases | M1: Estimated Severe Cases | N1: Cost inpatient bed day at Secondary level (US$ 2024) | O1: Cost per outpatient in health center (US$ 2024) | P1: Unit cost Uncomplicated | Q1: Unit Cost Severe | R1: DALYS malaria | S1: Programme Cost | T1: Incidence Rate (cases per thousand) | U1: Total Malaria Cases (Estimated)
A2: Angola | B2: Bengo | C2: 166425.88 | F2: 0 | G2: 235300 | H2: 537916 | I2: 30.465833 | J2: 689.7 | K2: 296.1 | L2: =IFERROR($H2*J2/100000,"") -> 3710.0067 | M2: =IFERROR($H2*K2/100000,"") -> 1592.7693 | N2: 49.2528 | O2: 6.5516 | P2: 9.79 | Q2: 69.055 | R2: 0.198 | S2: 56732.311 | T2: 200.77 | U2: =IFERROR($T2*$H2/1000,"") -> 107997.4
A3: Angola | B3: Bie | C3: 346453.99 | D3: 1442146 | E3: 1026886 | F3: 62229 | G3: 27610 | H3: 2043741 | I3: 22.409444 | J3: 689.7 | K3: 296.1 | L3: =IFERROR($H3*J3/100000,"") -> 14095.682 | M3: =IFERROR($H3*K3/100000,"") -> 6051.5171 | N3: 49.2528 | O3: 6.5516 | P3: 9.79 | Q3: 69.055 | R3: 0.198 | S3: 56732.311 | T3: 309.893 | U3: =IFERROR($T3*$H3/1000,"") -> 633341.03
A4: Angola | B4: Cuando Cubango | C4: 117611.63 | D4: 468242 | E4: 275097 | H4: 737307 | I4: 24.222778 | J4: 689.7 | K4: 296.1 | L4: =IFERROR($H4*J4/100000,"") -> 5085.2064 | M4: =IFERROR($H4*K4/100000,"") -> 2183.166 | N4: 49.2528 | O4: 6.5516 | P4: 9.79 | Q4: 69.055 | R4: 0.198 | S4: 56732.311 | T4: 253.497 | U4: =IFERROR($T4*$H4/1000,"") -> 186905.11
A5: Angola | B5: Cuanza Norte | C5: 110068.67 | F5: 134245 | G5: 197536 | H5: 604659 | I5: 11.254 | J5: 689.7 | K5: 296.1 | L5: =IFERROR($H5*J5/100000,"") -> 4170.3331 | M5: =IFERROR($H5*K5/100000,"") -> 1790.3953 | N5: 49.2528 | O5: 6.5516 | P5: 9.79 | Q5: 69.055 | R5: 0.198 | S5: 56732.311 | T5: 341.788 | U5: =IFERROR($T5*$H5/1000,"") -> 206665.19
A6: Angola | B6: Cuanza Sul | C6: 694473.42 | D6: 88063 | E6: 43292 | F6: 134388 | G6: 65863 | H6: 2580986 | I6: 9.74375 | J6: 689.7 | K6: 296.1 | L6: =IFERROR($H6*J6/100000,"") -> 17801.06 | M6: =IFERROR($H6*K6/100000,"") -> 7642.2995 | N6: 49.2528 | O6: 6.5516 | P6: 9.79 | Q6: 69.055 | R6: 0.198 | S6: 56732.311 | T6: 354.065 | U6: =IFERROR($T6*$H6/1000,"") -> 913836.81
A7: Angola | B7: Huambo | C7: 616511.62 | D7: 125195 | E7: 89663 | H7: 2865919 | I7: 6.355 | J7: 689.7 | K7: 296.1 | L7: =IFERROR($H7*J7/100000,"") -> 19766.243 | M7: =IFERROR($H7*K7/100000,"") -> 8485.9862 | N7: 49.2528 | O7: 6.5516 | P7: 9.79 | Q7: 69.055 | R7: 0.198 | S7: 56732.311 | T7: 353.293 | U7: =IFERROR($T7*$H7/1000,"") -> 1012509.1
A8: Angola | B8: Huila | C8: 961330.34 | D8: 872419 | E8: 538474 | F8: 69808 | G8: 161848 | H8: 3463351 | I8: 2.0621429 | J8: 689.7 | K8: 296.1 | L8: =IFERROR($H8*J8/100000,"") -> 23886.732 | M8: =IFERROR($H8*K8/100000,"") -> 10254.982 | N8: 49.2528 | O8: 6.5516 | P8: 9.79 | Q8: 69.055 | R8: 0.198 | S8: 56732.311 | T8: 289.84 | U8: =IFERROR($T8*$H8/1000,"") -> 1003817.7
A9: Angola | B9: Lunda Sul | C9: 139008.24 | D9: 68671 | E9: 44752 | F9: 514948 | G9: 195824 | H9: 750284 | I9: 1.33375 | J9: 689.7 | K9: 296.1 | L9: =IFERROR($H9*J9/100000,"") -> 5174.7087 | M9: =IFERROR($H9*K9/100000,"") -> 2221.5909 | N9: 49.2528 | O9: 6.5516 | P9: 9.79 | Q9: 69.055 | R9: 0.198 | S9: 56732.311 | T9: 256.389 | U9: =IFERROR($T9*$H9/1000,"") -> 192364.56
A10: Angola | B10: Uige | C10: 354487.75 | D10: 186245 | E10: 146735 | F10: 142728 | G10: 125010 | H10: 2032514 | I10: 7.685 | J10: 689.7 | K10: 296.1 | L10: =IFERROR($H10*J10/100000,"") -> 14018.249 | M10: =IFERROR($H10*K10/100000,"") -> 6018.274 | N10: 49.2528 | O10: 6.5516 | P10: 9.79 | Q10: 69.055 | R10: 0.198 | S10: 56732.311 | T10: 375.283 | U10: =IFERROR($T10*$H10/1000,"") -> 762767.95
A11: Benin | B11: Alibori | C11: 523611.09 | D11: 899911 | E11: 761218 | H11: 1092654 | I11: 0 | J11: 628.9 | K11: 225.4 | L11: =IFERROR($H11*J11/100000,"") -> 6871.701 | M11: =IFERROR($H11*K11/100000,"") -> 2462.8421 | N11: 8.0538 | O11: 1.65 | P11: 4.1 | Q11: 102.025 | R11: 0.197 | S11: 182830.4 | T11: 377.763 | U11: =IFERROR($T11*$H11/1000,"") -> 412764.25
A12: Benin | B12: Atakora | C12: 459453.55 | D12: 720007 | E12: 673607 | H12: 972740 | I12: 0 | J12: 628.9 | K12: 225.4 | L12: =IFERROR($H12*J12/100000,"") -> 6117.5619 | M12: =IFERROR($H12*K12/100000,"") -> 2192.556 | N12: 8.0538 | O12: 1.65 | P12: 4.1 | Q12: 102.025 | R12: 0.197 | S12: 182830.4 | T12: 388.753 | U12: =IFERROR($T12*$H12/1000,"") -> 378155.59
A13: Benin | B13: Atlantique | C13: 805362.62 | D13: 32367 | E13: 28345 | H13: 1761206 | I13: 0 | J13: 628.9 | K13: 225.4 | L13: =IFERROR($H13*J13/100000,"") -> 11076.225 | M13: =IFERROR($H13*K13/100000,"") -> 3969.7583 | N13: 8.0538 | O13: 1.65 | P13: 4.1 | Q13: 102.025 | R13: 0.197 | S13: 182830.4 | T13: 353.688 | U13: =IFERROR($T13*$H13/1000,"") -> 622917.43
A14: Benin | B14: Borgou | C14: 711488.7 | D14: 1259669 | E14: 1042667 | H14: 1529465 | I14: 0 | J14: 628.9 | K14: 225.4 | L14: =IFERROR($H14*J14/100000,"") -> 9618.8054 | M14: =IFERROR($H14*K14/100000,"") -> 3447.4141 | N14: 8.0538 | O14: 1.65 | P14: 4.1 | Q14: 102.025 | R14: 0.197 | S14: 182830.4 | T14: 372.001 | U14: =IFERROR($T14*$H14/1000,"") -> 568962.51
A15: Benin | B15: Collines | C15: 380559.94 | D15: 744315 | E15: 614893 | H15: 903733 | I15: 0 | J15: 628.9 | K15: 225.4 | L15: =IFERROR($H15*J15/100000,"") -> 5683.5768 | M15: =IFERROR($H15*K15/100000,"") -> 2037.0142 | N15: 8.0538 | O15: 1.65 | P15: 4.1 | Q15: 102.025 | R15: 0.197 | S15: 182830.4 | T15: 386.839 | U15: =IFERROR($T15*$H15/1000,"") -> 349599.17
A16: Benin | B16: Couffo | C16: 403346.33 | D16: 587470 | E16: 434102 | H16: 938813 | I16: 0 | J16: 628.9 | K16: 225.4 | L16: =IFERROR($H16*J16/100000,"") -> 5904.195 | M16: =IFERROR($H16*K16/100000,"") -> 2116.0845 | N16: 8.0538 | O16: 1.65 | P16: 4.1 | Q16: 102.025 | R16: 0.197 | S16: 182830.4 | T16: 380.465 | U16: =IFERROR($T16*$H16/1000,"") -> 357185.49
A17: Benin | B17: Donga | C17: 317117.3 | D17: 563444 | E17: 484339 | H17: 684124 | I17: 0 | J17: 628.9 | K17: 225.4 | L17: =IFERROR($H17*J17/100000,"") -> 4302.4558 | M17: =IFERROR($H17*K17/100000,"") -> 1542.0155 | N17: 8.0538 | O17: 1.65 | P17: 4.1 | Q17: 102.025 | R17: 0.197 | S17: 182830.4 | T17: 393.829 | U17: =IFERROR($T17*$H17/1000,"") -> 269427.87
A18: Benin | B18: Mono | C18: 262885.26 | D18: 74233 | E18: 58443 | H18: 626326 | I18: 0 | J18: 628.9 | K18: 225.4 | L18: =IFERROR($H18*J18/100000,"") -> 3938.9642 | M18: =IFERROR($H18*K18/100000,"") -> 1411.7388 | N18: 8.0538 | O18: 1.65 | P18: 4.1 | Q18: 102.025 | R18: 0.197 | S18: 182830.4 | T18: 379.063 | U18: =IFERROR($T18*$H18/1000,"") -> 237417.01
A19: Benin | B19: Oueme | C19: 525653.77 | D19: 46008 | E19: 36464 | H19: 1438490 | I19: 0 | J19: 628.9 | K19: 225.4 | L19: =IFERROR($H19*J19/100000,"") -> 9046.6636 | M19: =IFERROR($H19*K19/100000,"") -> 3242.3565 | N19: 8.0538 | O19: 1.65 | P19: 4.1 | Q19: 102.025 | R19: 0.197 | S19: 182830.4 | T19: 322.992 | U19: =IFERROR($T19*$H19/1000,"") -> 464620.76
A20: Benin | B20: Plateau | C20: 365150.01 | D20: 283869 | E20: 224604 | H20: 783938 | I20: 0 | J20: 628.9 | K20: 225.4 | L20: =IFERROR($H20*J20/100000,"") -> 4930.1861 | M20: =IFERROR($H20*K20/100000,"") -> 1766.9963 | N20: 8.0538 | O20: 1.65 | P20: 4.1 | Q20: 102.025 | R20: 0.197 | S20: 182830.4 | T20: 396.753 | U20: =IFERROR($T20*$H20/1000,"") -> 311029.75
A21: Benin | B21: Zou | C21: 448421.72 | D21: 562159 | E21: 481134 | H21: 1072649 | I21: 0 | J21: 628.9 | K21: 225.4 | L21: =IFERROR($H21*J21/100000,"") -> 6745.8896 | M21: =IFERROR($H21*K21/100000,"") -> 2417.7508 | N21: 8.0538 | O21: 1.65 | P21: 4.1 | Q21: 102.025 | R21: 0.197 | S21: 182830.4 | T21: 363.117 | U21: =IFERROR($T21*$H21/1000,"") -> 389497.09
A22: Burkina Faso | B22: Cascades | C22: 310345.08 | D22: 62326 | E22: 62322 | H22: 940692 | I22: 0 | J22: 2209.5 | K22: 427.2 | L22: =IFERROR($H22*J22/100000,"") -> 20784.59 | M22: =IFERROR($H22*K22/100000,"") -> 4018.6362 | N22: 6.5466 | O22: 1.4119 | P22: 4.1 | Q22: 102.025 | R22: 0.221 | S22: 1178887 | T22: 249.441 | U22: =IFERROR($T22*$H22/1000,"") -> 234647.15
A23: Burkina Faso | B23: Sud-Ouest | C23: 283876.61 | D23: 165625 | E23: 164321 | F23: =SUM(55716+101548) -> 157264 | G23: =SUM(55716+100862) -> 156578 | H23: 1013635 | I23: 0 | J23: 2209.5 | K23: 427.2 | L23: =IFERROR($H23*J23/100000,"") -> 22396.265 | M23: =IFERROR($H23*K23/100000,"") -> 4330.2487 | N23: 6.5466 | O23: 1.4119 | P23: 4.1 | Q23: 102.025 | R23: 0.221 | S23: 1178887 | T23: 279.393 | U23: =IFERROR($T23*$H23/1000,"") -> 283202.52
A24: Burundi | B24: Bubanza | C24: 124263.97 | D24: 568093 | E24: 464384 | H24: 560452 | I24: 0 | J24: 1081.3 | K24: 337.5 | L24: =IFERROR($H24*J24/100000,"") -> 6060.1675 | M24: =IFERROR($H24*K24/100000,"") -> 1891.5255 | N24: 1.8829 | O24: 0.5436 | P24: 3.18 | Q24: 36.035 | R24: 0.164 | S24: 349502.26 | T24: 236.61 | U24: =IFERROR($T24*$H24/1000,"") -> 132608.55
A25: Burundi | B25: Bujumbura (Mairie) | C25: 209761.07 | D25: 89366 | E25: 73166 | H25: 824315 | I25: 0 | J25: 1081.3 | K25: 337.5 | L25: =IFERROR($H25*J25/100000,"") -> 8913.3181 | M25: =IFERROR($H25*K25/100000,"") -> 2782.0631 | N25: 1.8829 | O25: 0.5436 | P25: 3.18 | Q25: 36.035 | R25: 0.164 | S25: 349502.26 | T25: 202.345 | U25: =IFERROR($T25*$H25/1000,"") -> 166796.02
A26: Burundi | B26: Bururi | C26: 33985.557 | D26: 458839 | E26: 373471 | H26: 856945 | I26: 0 | J26: 1081.3 | K26: 337.5 | L26: =IFERROR($H26*J26/100000,"") -> 9266.1463 | M26: =IFERROR($H26*K26/100000,"") -> 2892.1894 | N26: 1.8829 | O26: 0.5436 | P26: 3.18 | Q26: 36.035 | R26: 0.164 | S26: 349502.26 | T26: 58.528 | U26: =IFERROR($T26*$H26/1000,"") -> 50155.277
A27: Burundi | B27: Cibitoke | C27: 183081.6 | D27: 814665 | E27: 666112 | H27: 763414 | I27: 0 | J27: 1081.3 | K27: 337.5 | L27: =IFERROR($H27*J27/100000,"") -> 8254.7956 | M27: =IFERROR($H27*K27/100000,"") -> 2576.5222 | N27: 1.8829 | O27: 0.5436 | P27: 3.18 | Q27: 36.035 | R27: 0.164 | S27: 349502.26 | T27: 228.415 | U27: =IFERROR($T27*$H27/1000,"") -> 174375.21
A28: Burundi | B28: Makamba | C28: 165715.69 | D28: 80692 | E28: 67208 | H28: 714443 | I28: 0 | J28: 1081.3 | K28: 337.5 | L28: =IFERROR($H28*J28/100000,"") -> 7725.2722 | M28: =IFERROR($H28*K28/100000,"") -> 2411.2451 | N28: 1.8829 | O28: 0.5436 | P28: 3.18 | Q28: 36.035 | R28: 0.164 | S28: 349502.26 | T28: 231.173 | U28: =IFERROR($T28*$H28/1000,"") -> 165159.93
A29: Burundi | B29: Rutana | C29: 171153.98 | D29: 361670 | E29: 292886 | H29: 552970 | I29: 0 | J29: 1081.3 | K29: 337.5 | L29: =IFERROR($H29*J29/100000,"") -> 5979.2646 | M29: =IFERROR($H29*K29/100000,"") -> 1866.2738 | N29: 1.8829 | O29: 0.5436 | P29: 3.18 | Q29: 36.035 | R29: 0.164 | S29: 349502.26 | T29: 247.812 | U29: =IFERROR($T29*$H29/1000,"") -> 137032.6
A30: Cameroon | B30: Est | C30: 450062.58 | D30: 291555 | E30: 144005 | H30: 1469352 | I30: 56.433667 | J30: 1829 | K30: 240.1 | L30: =IFERROR($H30*J30/100000,"") -> 26874.448 | M30: =IFERROR($H30*K30/100000,"") -> 3527.9142 | N30: 13.7352 | O30: 2.4918 | P30: 9.79 | Q30: 69.05 | R30: 0.128 | S30: 291013.33 | T30: 338.012 | U30: =IFERROR($T30*$H30/1000,"") -> 496658.61
A31: Cameroon | B31: Extreme Nord | C31: 1421022.8 | D31: 601341 | E31: 378419 | H31: 5358825 | I31: 0.001515152 | J31: 1829 | K31: 240.1 | L31: =IFERROR($H31*J31/100000,"") -> 98012.909 | M31: =IFERROR($H31*K31/100000,"") -> 12866.539 | N31: 13.7352 | O31: 2.4918 | P31: 9.79 | Q31: 69.05 | R31: 0.128 | S31: 291013.33 | T31: 239.306 | U31: =IFERROR($T31*$H31/1000,"") -> 1282399
A32: Cameroon | B32: Littoral | C32: 1429297.5 | D32: 684587 | E32: 396616 | H32: 4487972 | I32: 31.910833 | J32: 1829 | K32: 240.1 | L32: =IFERROR($H32*J32/100000,"") -> 82085.008 | M32: =IFERROR($H32*K32/100000,"") -> 10775.621 | N32: 13.7352 | O32: 2.4918 | P32: 9.79 | Q32: 69.05 | R32: 0.128 | S32: 291013.33 | T32: 259.309 | U32: =IFERROR($T32*$H32/1000,"") -> 1163771.5
A33: Cameroon | B33: Nord | C33: 1029496.4 | D33: 1271317 | E33: 946109 | H33: 3242725 | I33: 0.80166667 | J33: 1829 | K33: 240.1 | L33: =IFERROR($H33*J33/100000,"") -> 59309.44 | M33: =IFERROR($H33*K33/100000,"") -> 7785.7827 | N33: 13.7352 | O33: 2.4918 | P33: 9.79 | Q33: 69.05 | R33: 0.128 | S33: 291013.33 | T33: 262.454 | U33: =IFERROR($T33*$H33/1000,"") -> 851066.15
A34: Cameroon | B34: Nord Ouest | C34: 600703.3 | D34: 1692293 | E34: 1171244 | H34: 2048193 | I34: 21.452857 | J34: 1829 | K34: 240.1 | L34: =IFERROR($H34*J34/100000,"") -> 37461.45 | M34: =IFERROR($H34*K34/100000,"") -> 4917.7114 | N34: 13.7352 | O34: 2.4918 | P34: 9.79 | Q34: 69.05 | R34: 0.128 | S34: 291013.33 | T34: 210.509 | U34: =IFERROR($T34*$H34/1000,"") -> 431163.06
A35: Cameroon | B35: Ouest | C35: 550840.05 | D35: 2067374 | E35: 2127572 | H35: 2514133 | I35: 20.62825 | J35: 1829 | K35: 240.1 | L35: =IFERROR($H35*J35/100000,"") -> 45983.493 | M35: =IFERROR($H35*K35/100000,"") -> 6036.4333 | N35: 13.7352 | O35: 2.4918 | P35: 9.79 | Q35: 69.05 | R35: 0.128 | S35: 291013.33 | T35: 206.936 | U35: =IFERROR($T35*$H35/1000,"") -> 520264.63
... A37: Cameroon | B37: Sud Ouest | C37: 646521.33 | D37: 1751337 | E37: 1150588 | H37: 2090068 | I37: 18.131429 | J37: 1829 | K37: 240.1 | L37: =IFERROR($H37*J37/100000,"") -> 38227.344 | M37: =IFERROR($H37*K37/100000,"") -> 5018.2533 | N37: 13.7352 | O37: 2.4918 | P37: 9.79 | Q37: 69.05 | R37: 0.128 | S37: 291013.33 | T37: 262.376 | U37: =IFERROR($T37*$H37/1000,"") -> 548383.68
A38: Chad | B38: Logone Occidental | C38: 167184.76 | F38: 465057 | G38: 427353 | H38: 1121837 | I38: 38.100625 | J38: 204.9 | K38: 146.2 | L38: =IFERROR($H38*J38/100000,"") -> 2298.644 | M38: =IFERROR($H38*K38/100000,"") -> 1640.1257 | N38: 8.5411 | O38: 1.7771 | P38: 9.75 | Q38: 36.035 | R38: 0.36 | S38: 188934.21 | T38: 164.084 | U38: =IFERROR($T38*$H38/1000,"") -> 184075.5
A39: Chad | B39: Logone Oriental | C39: 290005.93 | F39: 1191962 | G39: 978347 | H39: 1290288 | I39: 19.405455 | J39: 204.9 | K39: 146.2 | L39: =IFERROR($H39*J39/100000,"") -> 2643.8001 | M39: =IFERROR($H39*K39/100000,"") -> 1886.4011 | N39: 8.5411 | O39: 1.7771 | P39: 9.75 | Q39: 36.035 | R39: 0.36 | S39: 188934.21 | T39: 191.04 | U39: =IFERROR($T39*$H39/1000,"") -> 246496.62
A40: Chad | B40: Mandoul | C40: 236891.88 | D40: 672758 | E40: 574123 | F40: 270934 | G40: 216104 | H40: 1290288 | I40: 15.008333 | J40: 204.9 | K40: 146.2 | L40: =IFERROR($H40*J40/100000,"") -> 2643.8001 | M40: =IFERROR($H40*K40/100000,"") -> 1886.4011 | N40: 8.5411 | O40: 1.7771 | P40: 9.75 | Q40: 36.035 | R40: 0.36 | S40: 188934.21 | T40: 224.538 | U40: =IFERROR($T40*$H40/1000,"") -> 289718.69
A41: Chad | B41: Mayo Kebbi Est | C41: 338079.06 | D41: 550254 | E41: 455803 | F41: 53767 | G41: 43772 | H41: 1245894 | I41: 0.13884615 | J41: 204.9 | K41: 146.2 | L41: =IFERROR($H41*J41/100000,"") -> 2552.8368 | M41: =IFERROR($H41*K41/100000,"") -> 1821.497 | N41: 8.5411 | O41: 1.7771 | P41: 9.75 | Q41: 36.035 | R41: 0.36 | S41: 188934.21 | T41: 262.286 | U41: =IFERROR($T41*$H41/1000,"") -> 326780.55
...

Sheet Sheet2
A1: Country | B1: District | C1: Senior Program Mgr salary (mean) | D1: District Health Officer salary (mean) | E1: Fuel prices (Gasoline prices) USD
A2: Angola | B2: Bengo | C2: 46500 | D2: 12600 | E2: 0.327
A3: Angola | B3: Bie | C3: 46500.5 | D3: 12600 | E3: 0.327
A4: Angola | B4: Cuando Cubango | C4: 46501 | D4: 12600 | E4: 0.327
A5: Angola | B5: Cuanza Norte | C5: 46501.5 | D5: 12600 | E5: 0.327
A6: Angola | B6: Cuanza Sul | C6: 46502 | D6: 12600 | E6: 0.327
A7: Angola | B7: Huambo | C7: 46502.5 | D7: 12600 | E7: 0.327
A8: Angola | B8: Huila | C8: 46503 | D8: 12600 | E8: 0.327
A9: Angola | B9: Lunda Sul | C9: 46503.5 | D9: 12600 | E9: 0.327
A10: Angola | B10: Uige | C10: 46504 | D10: 12600 | E10: 0.327
A11: Benin | B11: Alibori | C11: 84037.815 | D11: 10500 | E11: 1.288
A12: Benin | B12: Atakora | C12: 84037.815 | D12: 10500 | E12: 1.288
A13: Benin | B13: Atlantique | C13: 84037.815 | D13: 10500 | E13: 1.288
... A203: Uganda | B203: Western | C203: 35598.01 | D203: 9900 | E203: 1.656

Sheet Sheet3
A1: Values for Ratios | B1: derived from: https://pmc.ncbi.nlm.nih.gov/articles/PMC7491157/” | E1: Source
A3: km_region | B3: 44.5 | C3: km | D3: mean distance from district centre to regional centre (one-way)
A4: fuel | B4: 0.12 | C4: USD, km | D4: USD per km of fuel in Toyota Cruiser
A5: food | B5: 8.1 | C5: USD, km | D5: Food allowance per meeting day per person
A7: leaflet | B7: 0.05 | C7: USD/unit | D7: price of a printed colour leaflet, A4
A8: district_dsa | B8: 17.07 | C8: USD/day | D8: District worker DSA
A9: district_wage | B9: 982.12 | C9: USD/day | D9: Cost of a district staff members wage
A10: central_regional_dsa | B10: 19.22 | C10: USD/day | D10: Cost of a central staff members per diem | E10: MACEPA mostly
A11: central_regional_wage | B11: 964.19 | C11: USD per month | D11: Mean monthly wage of program staff at central level
A12: driver_wage | B12: 310.5 | C12: USD/day | D12: Cost of a driver staff members wage
A17: drug_vol | B17: 82.32 | C17: cm3, per course | D17: Drug volume
A18: electricity | B18: 0.24 | C18: USD, kWh | D18: Price of electricity per Kwh
A22: chw_n_cen_plan_c | B22: 10 | C22: number | D22: planning meeting at central level - attendants from central level
A23: chw_n_cen_plan_d | B23: 5 | C23: number | D23: planning meeting at central level - attendants from district level
A24: chw_n_cen_plan_Days | B24: 3 | C24: number | D24: planning meeting days at central level
A25: chw_n_cen_plan_r | B25: 4 | C25: number | D25: planning meeting at central level - attendants from regional level
A26: chw_n_plan_c | B26: 10 | C26: number | D26: Micro Planning - attendants from central level
A27: chw_n_plan_d | B27: 6 | C27: number | D27: Micro Planning - attendants from district level
A28: chw_n_plan_r | B28: 2 | C28: number | D28: Micro Planning - attendants from regional level
A30: MDA_Days_plan_d | B30: 4 | C30: Days | D30: Days micro-planning intervention at district level
A31: MDA_Days_plan_r | B31: 4 | C31: Days | D31: Days micro-planning intervention at regional level
A33: cheap_hotel | B33: 28.99 | C33: USD | D33: cost of night accommodation in cheap hotel | E33: MACEPA/ zambia
A35: Combined Planning Cost per Country — one-day district planning meeting
A37: Meeting assumptions
A38: n_district_attendants | B38: 4 | C38: number | D38: District attendants per meeting
A39: meeting_days | B39: 1 | C39: days | D39: Meeting duration (one whole day)
A40: hotel_nights | B40: 1 | C40: nights | D40: Nights of accommodation for district workers
A41: leaflet_copies | B41: 1000 | C41: copies | D41: Printed leaflets per meeting
A42: round_trip_factor | B42: 2 | C42: number | D42: km_region is one-way, so ×2 for round trip
A43: working_days_per_year | B43: 260 | C43: days | D43: To convert annual salary to daily wage
A44: vehicle_consumption | B44: 0.13 | C44: L/km | D44: Fuel consumption of vehicle (to convert USD/L to USD/km)
A45: Country | B45: Fuel price (USD/L) | C45: Fuel ratio (USD/km vs 0.12 base) | D45: Transport (USD) | E45: Food (USD) | F45: Leaflets (USD) | G45: Accommodation (USD) | H45: DSA (USD) | I45: Staff time (USD) | J45: Total planning cost (USD)
A46: {=_xlfn.UNIQUE(Sheet2!A2:A203)} -> Angola | B46: =AVERAGEIF(Sheet2!$A$2:$A$203,$A46,Sheet2!$E$2:$E$203) -> 0.327 | C46: =B46*$B$44/$B$4 -> 0.35425 | D46: =$B$3*$B$42*$B$4*$C46 -> 3.78339 | E46: =$B$5*$C46*$B$38*$B$39 -> 11.4777 | F46: =$B$7*$B$41*$C46 -> 17.7125 | G46: =$B$33*$C46*$B$38*$B$40 -> 41.07883 | H46: =$B$8*$C46*$B$38*$B$39 -> 24.18819 | I46: =AVERAGEIF(Sheet2!$A$2:$A$203,$A46,Sheet2!$D$2:$D$203)/$B$43*$B$38*$B$39 -> 193.84615 | J46: =SUM(D46:I46) -> 292.08676
A47: Benin | B47: =AVERAGEIF(Sheet2!$A$2:$A$203,$A47,Sheet2!$E$2:$E$203) -> 1.288 | C47: =B47*$B$44/$B$4 -> 1.3953333 | D47: =$B$3*$B$42*$B$4*$C47 -> 14.90216 | E47: =$B$5*$C47*$B$38*$B$39 -> 45.2088 | F47: =$B$7*$B$41*$C47 -> 69.766667 | G47: =$B$33*$C47*$B$38*$B$40 -> 161.80285 | H47: =$B$8*$C47*$B$38*$B$39 -> 95.27336 | I47: =AVERAGEIF(Sheet2!$A$2:$A$203,$A47,Sheet2!$D$2:$D$203)/$B$43*$B$38*$B$39 -> 161.53846 | J47: =SUM(D47:I47) -> 548.4923
A48: Burkina Faso | B48: =AVERAGEIF(Sheet2!$A$2:$A$203,$A48,Sheet2!$E$2:$E$203) -> 1.51 | C48: =B48*$B$44/$B$4 -> 1.6358333 | D48: =$B$3*$B$42*$B$4*$C48 -> 17.4707 | E48: =$B$5*$C48*$B$38*$B$39 -> 53.001 | F48: =$B$7*$B$41*$C48 -> 81.791667 | G48: =$B$33*$C48*$B$38*$B$40 -> 189.69123 | H48: =$B$8*$C48*$B$38*$B$39 -> 111.6947 | I48: =AVERAGEIF(Sheet2!$A$2:$A$203,$A48,Sheet2!$D$2:$D$203)/$B$43*$B$38*$B$39 -> 342.92308 | J48: =SUM(D48:I48) -> 796.57238
A49: Burundi | B49: =AVERAGEIF(Sheet2!$A$2:$A$203,$A49,Sheet2!$E$2:$E$203) -> 1.343 | C49: =B49*$B$44/$B$4 -> 1.4549167 | D49: =$B$3*$B$42*$B$4*$C49 -> 15.53851 | E49: =$B$5*$C49*$B$38*$B$39 -> 47.1393 | F49: =$B$7*$B$41*$C49 -> 72.745833 | G49: =$B$33*$C49*$B$38*$B$40 -> 168.71214 | H49: =$B$8*$C49*$B$38*$B$39 -> 99.34171 | I49: =AVERAGEIF(Sheet2!$A$2:$A$203,$A49,Sheet2!$D$2:$D$203)/$B$43*$B$38*$B$39 -> 92.307692 | J49: =SUM(D49:I49) -> 495.78518
A50: Cameroon | B50: =AVERAGEIF(Sheet2!$A$2:$A$203,$A50,Sheet2!$E$2:$E$203) -> 1.491 | C50: =B50*$B$44/$B$4 -> 1.61525 | D50: =$B$3*$B$42*$B$4*$C50 -> 17.25087 | E50: =$B$5*$C50*$B$38*$B$39 -> 52.3341 | F50: =$B$7*$B$41*$C50 -> 80.7625 | G50: =$B$33*$C50*$B$38*$B$40 -> 187.30439 | H50: =$B$8*$C50*$B$38*$B$39 -> 110.28927 | I50: =AVERAGEIF(Sheet2!$A$2:$A$203,$A50,Sheet2!$D$2:$D$203)/$B$43*$B$38*$B$39 -> 84.923077 | J50: =SUM(D50:I50) -> 532.86421
A51: Chad | B51: =AVERAGEIF(Sheet2!$A$2:$A$203,$A51,Sheet2!$E$2:$E$203) -> 0.847 | C51: =B51*$B$44/$B$4 -> 0.91758333 | D51: =$B$3*$B$42*$B$4*$C51 -> 9.79979 | E51: =$B$5*$C51*$B$38*$B$39 -> 29.7297 | F51: =$B$7*$B$41*$C51 -> 45.879167 | G51: =$B$33*$C51*$B$38*$B$40 -> 106.40296 | H51: =$B$8*$C51*$B$38*$B$39 -> 62.65259 | I51: =AVERAGEIF(Sheet2!$A$2:$A$203,$A51,Sheet2!$D$2:$D$203)/$B$43*$B$38*$B$39 -> 133.84615 | J51: =SUM(D51:I51) -> 388.31036
A52: Congo | B52: =AVERAGEIF(Sheet2!$A$2:$A$203,$A52,Sheet2!$E$2:$E$203) -> 0.97 | C52: =B52*$B$44/$B$4 -> 1.0508333 | D52: =$B$3*$B$42*$B$4*$C52 -> 11.2229 | E52: =$B$5*$C52*$B$38*$B$39 -> 34.047 | F52: =$B$7*$B$41*$C52 -> 52.541667 | G52: =$B$33*$C52*$B$38*$B$40 -> 121.85463 | H52: =$B$8*$C52*$B$38*$B$39 -> 71.7509 | I52: =AVERAGEIF(Sheet2!$A$2:$A$203,$A52,Sheet2!$D$2:$D$203)/$B$43*$B$38*$B$39 -> 147.69231 | J52: =SUM(D52:I52) -> 439.10941
A53: Cote d'Ivoire | B53: =AVERAGEIF(Sheet2!$A$2:$A$203,$A53,Sheet2!$E$2:$E$203) -> 1.554 | C53: =B53*$B$44/$B$4 -> 1.6835 | D53: =$B$3*$B$42*$B$4*$C53 -> 17.97978 | E53: =$B$5*$C53*$B$38*$B$39 -> 54.5454 | F53: =$B$7*$B$41*$C53 -> 84.175 | G53: =$B$33*$C53*$B$38*$B$40 -> 195.21866 | H53: =$B$8*$C53*$B$38*$B$39 -> 114.94938 | I53: =AVERAGEIF(Sheet2!$A$2:$A$203,$A53,Sheet2!$D$2:$D$203)/$B$43*$B$38*$B$39 -> 330.76923 | J53: =SUM(D53:I53) -> 797.63745
...
